<?xml version="1.0"?>
<robot xmlns:xacro="http://www.ros.org/wiki/xacro" >

    <xacro:include filename="inertial_macros.xacro"/>
    <material name="white">
        <color rgba="1 1 1 1" />
    </material>

    <material name="orange">
        <color rgba="1 0.3 0.1 1" />
    </material>

    <material name="blue">
        <color rgba="0.2 0.2 1 1" />
    </material>

    <material name="black">
        <color rgba="0 0 0 1" />
    </material>

    <!-- BASE LINK-->

    <link name="base_link">

    </link>

        <!-- CHASSIS LINK-->

    <joint name="chassis_joint" type="fixed">
        <parent link="base_link"/>
        <child link="chassis"/>
        <origin xyz="0 0 0.01"/>
    </joint>

    <link name="chassis">
        <visual>
            <origin xyz="0 0 0.0175"/>
            <geometry>
                <cylinder length="0.035" radius="0.07"/>
            </geometry>
            <material name="orange"/>
        </visual>
        <collision>
            <origin xyz="0 0 0.0175"/>
            <geometry>
                <cylinder length="0.035" radius="0.07"/>
            </geometry>
        </collision>
        <xacro:inertial_cylinder mass="0.5" length="0.035" radius="0.07">
            <origin xyz="0 0 0.0175" rpy="0 0 0"/>
        </xacro:inertial_cylinder>
    </link>

    <gazebo reference="chassis">
        <material>Gazebo/Orange</material>
    </gazebo>

    <!-- LEFT WHEEL LINK-->

    <joint name= "left_wheel_joint" type="continuous">
        <parent link="base_link"/>
        <child link="left_wheel"/>
        <origin xyz="0 0.06 0" rpy="-${pi/2} 0 0"/>
        <axis xyz="0 0 1"/>
    </joint>

    <link name="left_wheel">
        <visual>
            <geometry>
                <cylinder radius="0.0325" length="0.025"/>
            </geometry>
            <material name="black"/>
        </visual>
        <collision>
            <geometry>
                <cylinder radius="0.0325" length="0.025"/>
            </geometry>
        </collision>
        <xacro:inertial_cylinder mass="0.1" length="0.025" radius="0.0325">
            <origin xyz="0 0 0" rpy="0 0 0"/>
        </xacro:inertial_cylinder>
    </link>

    <gazebo reference="left_wheel">
        <material>Gazebo/Black</material>
    </gazebo>

    <!-- RIGHT WHEEL LINK-->

    <joint name= "right_wheel_joint" type="continuous">
        <parent link="base_link"/>
        <child link="right_wheel"/>
        <origin xyz="0 -0.06 0" rpy="${pi/2} 0 0"/>
        <axis xyz="0 0 -1"/>
    </joint>

    <link name="right_wheel">
        <visual>
            <geometry>
                <cylinder radius="0.0325" length="0.025"/>
            </geometry>
            <material name="black"/>
        </visual>
        <collision>
            <geometry>
                <cylinder radius="0.0325" length="0.025"/>
            </geometry>
        </collision>
        <xacro:inertial_cylinder mass="0.1" length="0.025" radius="0.0325">
            <origin xyz="0 0 0" rpy="0 0 0"/>
        </xacro:inertial_cylinder>
    </link>

    <gazebo reference="right_wheel">
        <material>Gazebo/Black</material>
    </gazebo>


    <!-- CASTER FRONT WHEEL-->

    <joint name="caster_wheel_front_joint" type="fixed">
        <parent link="chassis"/>
        <child link="caster_wheel_front"/>
        <origin xyz="0.05 0 -0.015"/>
    </joint>

    <link name="caster_wheel_front">
        <visual>
            <geometry>
                <sphere radius="0.0275"/>
            </geometry>
            <material name="white"/>
        </visual>
        <collision>
            <geometry>
                <sphere radius="0.0275"/>
            </geometry>
        </collision>
        <xacro:inertial_sphere mass="0.1" radius="0.0275">
            <origin xyz="0 0 0" rpy="0 0 0"/>
        </xacro:inertial_sphere>
    </link>

    <gazebo reference="caster_wheel_front">
        <material>Gazebo/White</material>
        <mu1 value="0.001"/>
        <mu2 value="0.001"/>
    </gazebo>


    <!-- CASTER BACK WHEEL-->

    <joint name="caster_wheel_back_joint" type="fixed">
        <parent link="chassis"/>
        <child link="caster_wheel_back"/>
        <origin xyz="-0.05 0 -0.015"/>
    </joint>

    <link name="caster_wheel_back">
        <visual>
            <geometry>
                <sphere radius="0.0275"/>
            </geometry>
            <material name="white"/>
        </visual>
        <collision>
            <geometry>
                <sphere radius="0.0275"/>
            </geometry>
        </collision>
        <xacro:inertial_sphere mass="0.1" radius="0.0275">
            <origin xyz="0 0 0" rpy="0 0 0"/>
        </xacro:inertial_sphere>
    </link>

    <gazebo reference="caster_wheel_back">
        <material>Gazebo/White</material>
        <mu1 value="0.001"/>
        <mu2 value="0.001"/>
    </gazebo>

</robot>